Workbook
Name Slicer_Category: #N/A
Name Slicer_Sales_Channel: #N/A

Sheet Ecommerce_Data
A1: Order_ID | B1: Order_Date | C1: Customer_ID | D1: Customer_Name | E1: Customer_Age | F1: Customer_Type | G1: Product_ID | H1: Product_Name | I1: Category | J1: Supplier | K1: Quantity | L1: Unit_Price | M1: Discount_% | N1: Gross_Sales | O1: Discount_Amount | P1: Net_Sales | Q1: Cost | R1: Profit | S1: Customer_Segment | T1: City | U1: State | V1: Country | W1: Payment_Method | X1: Sales_Channel | Y1: Shipping_Mode | Z1: Order_Status | AA1: Returned_Flag | AB1: Priority_Order
A2: ORD504535 | B2: 45292 | C2: CUST11195 | D2: Customer 1195 | E2: 24 | F2: New | G2: P1001 | H2: Laptop | I2: Electronics | J2: TechSource India | K2: 5 | L2: 55000 | M2: 5 | N2: 275000 | O2: 13750 | P2: 261250 | Q2: 154257.47 | R2: 106992.53 | S2: Corporate | T2: Nagpur | U2: Maharashtra | V2: India | W2: Wallet | X2: Website | Y2: Express | Z2: Delivered | AA2: No | AB2: No
A3: ORD505568 | B3: 45292 | C3: CUST11710 | D3: Customer 1710 | E3: 60 | F3: Returning | G3: P5001 | H3: Notebook Set | I3: Books & Stationery | J3: Stationery Hub | K3: 1 | L3: 500 | M3: 10 | N3: 500 | O3: 50 | P3: 450 | Q3: 249.47 | R3: 200.53 | S3: Consumer | T3: Bengaluru | U3: Karnataka | V3: India | W3: Wallet | X3: Website | Y3: Standard | Z3: Delivered | AA3: No | AB3: No
A4: ORD504539 | B4: 45292 | C4: CUST11745 | D4: Customer 1745 | E4: 41 | F4: Returning | G4: P3004 | H4: Cookware Set | I4: Home & Kitchen | J4: HomeNeeds | K4: 1 | L4: 3500 | M4: 5 | N4: 3500 | O4: 175 | P4: 3325 | Q4: 2450.65 | R4: 874.35 | S4: Home Office | T4: Chandigarh | U4: Chandigarh | V4: India | W4: Cash on Delivery | X4: Marketplace | Y4: Standard | Z4: Delivered | AA4: No | AB4: Yes
A5: ORD507248 | B5: 45292 | C5: CUST12458 | D5: Customer 2458 | E5: 59 | F5: New | G5: P2002 | H5: Jeans | I5: Fashion | J5: FashionMart | K5: 1 | L5: 2200 | M5: 10 | N5: 2200 | O5: 220 | P5: 1980 | Q5: 1504.4 | R5: 475.6 | S5: Consumer | T5: Patna | U5: Bihar | V5: India | W5: Wallet | X5: Marketplace | Y5: Express | Z5: Delivered | AA5: No | AB5: No
A6: ORD507572 | B6: 45292 | C6: CUST12425 | D6: Customer 2425 | E6: 52 | F6: Returning | G6: P5005 | H6: Desk Organizer | I6: Books & Stationery | J6: Stationery Hub | K6: 1 | L6: 600 | M6: 10 | N6: 600 | O6: 60 | P6: 540 | Q6: 352.39 | R6: 187.61 | S6: Corporate | T6: Bengaluru | U6: Karnataka | V6: India | W6: Net Banking | X6: Website | Y6: Same Day | Z6: Delivered | AA6: No | AB6: No
A7: ORD501934 | B7: 45292 | C7: CUST12401 | D7: Customer 2401 | E7: 47 | F7: Returning | G7: P3001 | H7: Coffee Maker | I7: Home & Kitchen | J7: HomeNeeds | K7: 4 | L7: 4200 | M7: 5 | N7: 16800 | O7: 840 | P7: 15960 | Q7: 13080.5 | R7: 2879.5 | S7: Consumer | T7: Bhopal | U7: Madhya Pradesh | V7: India | W7: Debit Card | X7: Marketplace | Y7: Standard | Z7: Delivered | AA7: No | AB7: No
A8: ORD504008 | B8: 45292 | C8: CUST10053 | D8: Customer 53 | E8: 20 | F8: New | G8: P3001 | H8: Coffee Maker | I8: Home & Kitchen | J8: HomeNeeds | K8: 1 | L8: 4200 | M8: 0 | N8: 4200 | O8: 0 | P8: 4200 | Q8: 2492.83 | R8: 1707.17 | S8: Consumer | T8: Delhi | U8: Delhi | V8: India | W8: Net Banking | X8: Mobile App | Y8: Same Day | Z8: Delivered | AA8: No | AB8: No
A9: ORD504805 | B9: 45292 | C9: CUST10308 | D9: Customer 308 | E9: 22 | F9: Returning | G9: P4005 | H9: Perfume | I9: Beauty | J9: BeautyCare | K9: 3 | L9: 1800 | M9: 20 | N9: 5400 | O9: 1080 | P9: 4320 | Q9: 3169.29 | R9: 1150.71 | S9: Home Office | T9: Lucknow | U9: Uttar Pradesh | V9: India | W9: Cash on Delivery | X9: Mobile App | Y9: Express | Z9: Processing | AA9: No | AB9: No
A10: ORD508540 | B10: 45292 | C10: CUST12035 | D10: Customer 2035 | E10: 59 | F10: Loyal | G10: P4002 | H10: Moisturizer | I10: Beauty | J10: BeautyCare | K10: 2 | L10: 650 | M10: 5 | N10: 1300 | O10: 65 | P10: 1235 | Q10: 822 | R10: 413 | S10: Consumer | T10: Hyderabad | U10: Telangana | V10: India | W10: Wallet | X10: Marketplace | Y10: Standard | Z10: Delivered | AA10: No | AB10: No
A11: ORD508071 | B11: 45292 | C11: CUST10701 | D11: Customer 701 | E11: 46 | F11: New | G11: P3003 | H11: Mixer Grinder | I11: Home & Kitchen | J11: Prime Distributors | K11: 1 | L11: 4800 | M11: 0 | N11: 4800 | O11: 0 | P11: 4800 | Q11: 3614.33 | R11: 1185.67 | S11: Consumer | T11: Surat | U11: Gujarat | V11: India | W11: UPI | X11: Mobile App | Y11: Standard | Z11: Delivered | AA11: Yes | AB11: No
A12: ORD507295 | B12: 45292 | C12: CUST11016 | D12: Customer 1016 | E12: 35 | F12: Returning | G12: P2008 | H12: Formal Shirt | I12: Fashion | J12: Global Traders | K12: 1 | L12: 1700 | M12: 15 | N12: 1700 | O12: 255 | P12: 1445 | Q12: 806 | R12: 639 | S12: Home Office | T12: Lucknow | U12: Uttar Pradesh | V12: India | W12: Cash on Delivery | X12: Mobile App | Y12: Same Day | Z12: Delivered | AA12: No | AB12: Yes
A13: ORD509961 | B13: 45292 | C13: CUST10199 | D13: Customer 199 | E13: 38 | F13: New | G13: P3007 | H13: Vacuum Cleaner | I13: Home & Kitchen | J13: Global Traders | K13: 1 | L13: 8500 | M13: 0 | N13: 8500 | O13: 0 | P13: 8500 | Q13: 6465.1 | R13: 2034.9 | S13: Consumer | T13: Mumbai | U13: Maharashtra | V13: India | W13: Credit Card | X13: Website | Y13: Standard | Z13: Delivered | AA13: No | AB13: No
... A12001: ORD510204 | B12001: 46254 | C12001: CUST11040 | D12001: Customer 1040 | E12001: 44 | F12001: New | G12001: P1008 | H12001: Monitor | I12001: Electronics | J12001: Global Traders | K12001: 1 | L12001: 14500 | M12001: 10 | N12001: 14500 | O12001: 1450 | P12001: 13050 | Q12001: 8655.83 | R12001: 4394.17 | S12001: Consumer | T12001: Delhi | U12001: Delhi | V12001: India | W12001: Debit Card | X12001: Mobile App | Y12001: Express | Z12001: Returned | AA12001: No | AB12001: No

Sheet Basic_Formulas
A1: A. SUM | F1: B. AVERAGE | L1: C. MIN/MAX
A3: Q1. Calculate the Total Quantity Sold. | F3: Q7. Find the average Unit Price. | L3: Q11. Find the highest Net Sales.
A4: =SUM(Ecommerce_Data!K2:K12001) -> 25786 | F4: =AVERAGE(Ecommerce_Data!L2:L12001) -> 5117.8083 | L4: =MAX(Ecommerce_Data!P2:P12001) -> 330000
A6: Q2. Calculate Total Gross Sale. | F6: Q8. Find the average Quantity per Order. | L6: Q12. Find the lowest Net Sales.
A7: =SUM(Ecommerce_Data!N2:N12001) -> 129627900 | F7: =AVERAGE(Ecommerce_Data!K2:K12001) -> 2.1488333 | L7: =MIN(Ecommerce_Data!P2:P12001) -> 175
A9: Q3. Calculate Total Discount Amount. | F9: Q9. Find the average Net Sales. | L9: Q13. Find the Highest Profit.
A10: =SUM(Ecommerce_Data!O2:O12001) -> 14609475 | F10: =AVERAGE(Ecommerce_Data!P2:P12001) -> 9584.8687 | L10: =MAX(Ecommerce_Data!R2:R12001) -> 113909.51
A12: Q4. Calculate Total Net Sales. | F12: Q10. Find the average Profit. | L12: Q14. Find the lowest Profit.
A13: =SUM(Ecommerce_Data!P2:P12001) -> 115018425 | F13: =AVERAGE(Ecommerce_Data!R2:R12001) -> 3007.3917 | L13: =MIN(Ecommerce_Data!R2:R12001) -> 35.3
A15: Q5. Calculate Total Cost. | L15: Q15. Find the highest Quantity purchased in one order.
A16: =SUM(Ecommerce_Data!Q2:Q12001) -> 78929725 | L16: =MAX(Ecommerce_Data!K2:K12001) -> 6
A18: Q6. Calculate Total Profit.
A19: =SUM(Ecommerce_Data!R2:R12001) -> 36088700
A22: D. COUNT/COUNTA | G22: E. ROUND | N22: F. BASIC CALCULATIONS
A24: Q16. Count the number of numeric Quantity entries. | G24: Q20. Calculate average Net Sales rounded to 2 decimals. | N24: Q23. Calculate Gross Sales for Order ID ORD10001.
A25: =COUNT(Ecommerce_Data!K2:K12001) -> 12000 | G25: =ROUND(AVERAGE(Ecommerce_Data!P2:P12001),2) -> 9584.87 | N25: =Ecommerce_Data!K2*Ecommerce_Data!L2 -> 275000
A27: Q17. Count the number of Order IDs. | G27: Q21. Calculate avg. profit rounded to the nearest whole no. | N27: Q24. Calculate Net Sales for Order ID ORD10001.
A28: =COUNTA(Ecommerce_Data!A2:A12001) -> 12000 | G28: =ROUND(AVERAGE(Ecommerce_Data!R2:R12001),0) -> 3007 | N28: =Ecommerce_Data!N2-Ecommerce_Data!O2 -> 261250
A30: Q18. Count the number of Customer Names. | G30: Q22. Calculate total Profit in thousands, rounded to 2 decimals. | N30: Q25. Calculate Discount Amount for Order ID ORD10001.
A31: =COUNTA(Ecommerce_Data!D2:D12001) -> 12000 | G31: =ROUND(SUM(Ecommerce_Data!R2:R12001)/1000,2) -> 36088.7 | N31: =Ecommerce_Data!N2*Ecommerce_Data!M2/100 -> 13750
A33: Q19. Count the number of Product Names. | N33: Q26. Calculate Cost per Unit for Order ID ORD10001.
A34: =COUNTA(Ecommerce_Data!H2:H12001) -> 12000 | N34: =Ecommerce_Data!Q2/Ecommerce_Data!K2 -> 30851.494

Sheet IF_Formulas
A1: A. SIMPLE IF
A3: Q1. For Order ID in row 2, if Net Sales are ₹50,000 or more, display "High" or else "Low". | L3: =IF(Ecommerce_Data!P2>=50000,"High","Low") -> High
A5: Q2. For OrderID in row 4, if Quantity is 3 or more, display "Bulk Order", or else "Regular Order". | L5: =IF(Ecommerce_Data!K4>=3,"Bulk Order","Regular Order") -> Regular Order
A7: Q3. For OrderID in row 6, if the Order Status is "Returned", display Returned Order or Not Returned. | L7: =IF(Ecommerce_Data!Z6="Returned","Returned Order","Not Returned") -> Not Returned
A9: B. NESTED IF
A11: Q4. For OrderID in row 7, classify Net Sales as: | F11: ₹50,000 or more ->Excellent | L11: =IF(Ecommerce_Data!P7>=50000,"Excellent",IF(Ecommerce_Data!P7>=25000,"Good",IF(Ecommerce_Data!P7>=10000,"Average","Low"))) -> Average
F12: ₹25,000 or more -> Good
F13: ₹10,000 or more -> Average
F14: Below ₹10,000 -> Low
A16: Q5. For OrderID in row 9, classify Customer Age: | F16: 50 or above -> Senior | L16: =IF(Ecommerce_Data!E9>=50,"Senior",IF(Ecommerce_Data!E9>=30,"Adult",IF(Ecommerce_Data!E9>=18,"Young Adult","Invalid"))) -> Young Adult
F17: 30-49 -> Adult
F18: 18-29 -> Young Adult
F19: Below 18 -> Invalid
A21: C. IF + AND
A23: Q6. For OrderID in row 12, if Quantity is at least 3 AND Discount is at least 15%, | L23: =IF(AND(Ecommerce_Data!K12>=3,Ecommerce_Data!M12>=15),"Bulk Discount","Regular") -> Regular
A24: display "Bulk Discount", otherwise "Regular".
A26: Q7. For OrderID in row 11, if Net Sales are at least ₹50,000 AND Profit is at least ₹10,000, | L26: =IF(AND(Ecommerce_Data!P11>=50000,Ecommerce_Data!R11>=10000),"Excellent Order","Normal Order") -> Normal Order
A27: display "Excellent Order", otherwise "Normal Order".
A29: D. IF + OR
A31: Q8. For OrderID in row 14, if Sales Channel is Website OR Mobile App, display "Direct Sales", | L31: =IF(OR(Ecommerce_Data!X14="Website",Ecommerce_Data!X14="Mobile App"),"Direct Sales","Marketplace") -> Direct Sales
A32: otherwise "Marketplace".
A34: Q9. For OrderId in row 15, if Payment Method is UPI OR Credit Card, display "digital Payment", | L34: =IF(OR(Ecommerce_Data!W15="UPI",Ecommerce_Data!W15="Credit Card"),"Digital Payment","Other Payment") -> Other Payment
A35: otherwise "Other Payment".
A37: E. IF + NOT
A39: Q10. For OrderID in row 16, if the order is NOT Cancelled,display "Valid Order", | L39: =IF(NOT(Ecommerce_Data!Z16="Cancelled"),"Valid Order","Cancelled") -> Valid Order
A40: otherwise "Cancelled".
A42: Q11. For OrderID in row 17, if the Customer Type is NOT New, display "Existing Customer", | L42: =IF(NOT(Ecommerce_Data!F17="New"),"Existing Customer","New Customer") -> Existing Customer
A43: otherwise "New Customer".
A45: F. IFERROR
A47: Q12. For OrderID in row 18, calculate profit margin. If an error occurs, display "N/A". | L47: =IFERROR(Ecommerce_Data!R18/Ecommerce_Data!P18,"N/A") -> 0.20160317
A49: Q13. For OrderID in row 19, calculate Revenue per Unit. If an error occurs, display "N/A". | L49: =IFERROR(Ecommerce_Data!P19/Ecommerce_Data!K19,"N/A") -> 1350

Sheet Text_Formulas
A1: Q1. For the Customer Name in Order row 20, convert the name to uppercase.
A2: =UPPER(Ecommerce_Data!D20) -> CUSTOMER 960
A4: Q2. For the Product Name in Order 22, Convert it into Proper Case.
A5: =PROPER(Ecommerce_Data!H22) -> Formal Shirt
A7: Q3. For the Product Name in Order row 24, find the number of characters.
A8: =LEN(Ecommerce_Data!H24) -> 8
A10: Q4. For the Customer name in Order row 25, extract the first 5 characters.
A11: =LEFT(Ecommerce_Data!D25,5) -> Custo
A13: Q5. For the Customer name in Order row 23, remove extra spaces.
A14: =TRIM(Ecommerce_Data!D23) -> Customer 130
A16: Q6. Combine Product Name and Category in Order row 21.
A17: =CONCATENATE(Ecommerce_Data!H21,"-",Ecommerce_Data!I21) -> Smartwatch-Electronics
A19: Q7. Combine Customer Name and City, in Order Row 25.
A20: =CONCATENATE(Ecommerce_Data!D25,"-",Ecommerce_Data!T25) -> Customer 1395-Chandigarh
A22: Q8. Find the position of the space in Customer Name, for Order row 24.
A23: =FIND(" ",Ecommerce_Data!D24) -> 9

Sheet Date&Time_Formulas
A1: Q1. For the order in Row 20, find the year of the Order Date.
A2: =YEAR(Ecommerce_Data!B20) -> 2024
A4: Q2. For the order in row 35, find the month number of the Order Date.
A5: =MONTH(Ecommerce_Data!B35) -> 1
A7: Q3. For the order in Row 50, find the day of the Order Date.
A8: =DAY(Ecommerce_Data!B50) -> 5
A10: Q4. Calculate the number of days from the Order Date of Row 65 until today.
A11: =TODAY()-Ecommerce_Data!B65 -> 969
A13: Q5. For the order in Row 80, find the weekday number of the Order Date.
A14: =WEEKDAY(Ecommerce_Data!B80) -> 1
A16: Q6. For the order in Row 110, display the month name of the Order Date.
A17: =TEXT(Ecommerce_Data!B110,"mmmm") -> January
A19: Q7. Find the number of days between the Order Date of Row 170 & 28-Aug-2026.
A20: =_xlfn.DAYS(DATE(2026,8,28),Ecommerce_Data!B170) -> 957
A22: Q8. Find the last date of the month following the Order Date in Row 200.
A23: =EOMONTH(Ecommerce_Data!B200,1) -> 45351
A25: Q9. Display the current date and time.
A26: =NOW() -> 46266.329
A28: Q10. Display the Order Date of Row 245 in the format DD-MMM-YYYY.
A29: =TEXT(Ecommerce_Data!B245,"dd-mmm-yyyy") -> 21-Jan-2024

Sheet VLOOKUP
A1: Q1. Find the Customer Name for the Order in Row 250. | J1: =VLOOKUP(Ecommerce_Data!A250,Ecommerce_Data!$A$2:$AB$12001,4,0) -> Customer 734
A3: Q2. Find the Customer Age for the order in Row 400. | J3: =VLOOKUP(Ecommerce_Data!A400,Ecommerce_Data!$A$2:$AB$12001,5,0) -> 28
A5: Q3. Find the Product Name for the order in Row 850. | J5: =VLOOKUP(Ecommerce_Data!A850,Ecommerce_Data!$A$2:$AB$12001,8,0) -> Womens Kurti
A7: Q4. Find the Supplier for the order in Row 1150. | J7: =VLOOKUP(Ecommerce_Data!A1150,Ecommerce_Data!$A$2:$AB$12001,10,0) -> FashionMart
A9: Q5. Find the Quantity for the order in Row 1300. | J9: =VLOOKUP(Ecommerce_Data!A1300,Ecommerce_Data!$A$2:$AB$12001,11,0) -> 1
A11: Q6. Find the Net Sales for the order in Row 2050. | J11: =VLOOKUP(Ecommerce_Data!A2050,Ecommerce_Data!$A$2:$AB$12001,16,0) -> 6840
A13: Q7. Find the Profit for the order in Row 2350. | J13: =VLOOKUP(Ecommerce_Data!A2350,Ecommerce_Data!$A$2:$AB$12001,18,0) -> 14217.66
A15: Q8. Find the City for the order in Row 2650. | J15: =VLOOKUP(Ecommerce_Data!A2650,Ecommerce_Data!$A$2:$AB$12001,20,0) -> Chennai
A17: Q9. Find the State for the order in Row 2800. | J17: =VLOOKUP(Ecommerce_Data!A2800,Ecommerce_Data!$A$2:$AB$12001,21,0) -> Chandigarh
A19: Q10. Find the Priority Order status for the order in Row 3700. | J19: =VLOOKUP(Ecommerce_Data!A3700,Ecommerce_Data!$A$2:$AB$12001,28,0) -> No
A21: Q11. Find the Returned Flag for the order in Row 3550. | J21: =VLOOKUP(Ecommerce_Data!A3550,Ecommerce_Data!$A$2:$AB$12001,27,0) -> Yes
A23: Q12. Find the Shipping Mode for the order in Row 3250. | J23: =VLOOKUP(Ecommerce_Data!A3250,Ecommerce_Data!$A$2:$AB$12001,25,0) -> Standard

Sheet HLOOKUP
A1: Field | B1: Order 1 | C1: Order 2 | D1: Order 3 | E1: Order 4 | F1: Order 5
A2: Order_ID | B2: =Ecommerce_Data!A250 -> ORD501194 | C2: =Ecommerce_Data!A400 -> ORD502140 | D2: =Ecommerce_Data!A550 -> ORD510622 | E2: =Ecommerce_Data!A700 -> ORD507461 | F2: =Ecommerce_Data!A850 -> ORD511472
A3: Customer_Name | B3: =Ecommerce_Data!D250 -> Customer 734 | C3: =Ecommerce_Data!D400 -> Customer 1817 | D3: =Ecommerce_Data!D550 -> Customer 1481 | E3: =Ecommerce_Data!D700 -> Customer 2437 | F3: =Ecommerce_Data!D850 -> Customer 701
A4: Product_Name | B4: =Ecommerce_Data!H250 -> Calculator | C4: =Ecommerce_Data!H400 -> Power Bank | D4: =Ecommerce_Data!H550 -> Coffee Maker | E4: =Ecommerce_Data!H700 -> Formal Shirt | F4: =Ecommerce_Data!H850 -> Womens Kurti
A5: Category | B5: =Ecommerce_Data!I250 -> Books & Stationery | C5: =Ecommerce_Data!I200 -> Fashion | D5: =Ecommerce_Data!I550 -> Home & Kitchen | E5: =Ecommerce_Data!I700 -> Fashion | F5: =Ecommerce_Data!I850 -> Fashion
A6: Quantity | B6: =Ecommerce_Data!K250 -> 4 | C6: =Ecommerce_Data!K200 -> 3 | D6: =Ecommerce_Data!K550 -> 1 | E6: =Ecommerce_Data!K700 -> 2 | F6: =Ecommerce_Data!K850 -> 4
A7: Unit_Price | B7: =Ecommerce_Data!L250 -> 650 | C7: =Ecommerce_Data!L200 -> 2600 | D7: =Ecommerce_Data!L550 -> 4200 | E7: =Ecommerce_Data!L700 -> 1700 | F7: =Ecommerce_Data!L850 -> 1400
A8: Discount_% | B8: =Ecommerce_Data!M250 -> 15 | C8: =Ecommerce_Data!M200 -> 10 | D8: =Ecommerce_Data!M550 -> 10 | E8: =Ecommerce_Data!M700 -> 20 | F8: =Ecommerce_Data!M850 -> 15
A9: Gross_Sales | B9: =Ecommerce_Data!N250 -> 2600 | C9: =Ecommerce_Data!N200 -> 7800 | D9: =Ecommerce_Data!N550 -> 4200 | E9: =Ecommerce_Data!N700 -> 3400 | F9: =Ecommerce_Data!N850 -> 5600
A10: Net_Sales | B10: =Ecommerce_Data!P250 -> 2210 | C10: =Ecommerce_Data!P200 -> 7020 | D10: =Ecommerce_Data!P550 -> 3780 | E10: =Ecommerce_Data!P700 -> 2720 | F10: =Ecommerce_Data!P850 -> 4760
A11: Profit | B11: =Ecommerce_Data!R250 -> 822.61 | C11: =Ecommerce_Data!R200 -> 1854.34 | D11: =Ecommerce_Data!R550 -> 1353.11 | E11: =Ecommerce_Data!R700 -> 761.51 | F11: =Ecommerce_Data!R850 -> 1885.01
A12: City | B12: =Ecommerce_Data!T250 -> Bengaluru | C12: =Ecommerce_Data!T200 -> Guwahati | D12: =Ecommerce_Data!T550 -> Bhubaneswar | E12: =Ecommerce_Data!T700 -> Kolkata | F12: =Ecommerce_Data!T850 -> Chennai
A13: Payment_Method | B13: =Ecommerce_Data!W250 -> Net Banking | C13: =Ecommerce_Data!W200 -> Credit Card | D13: =Ecommerce_Data!W550 -> Wallet | E13: =Ecommerce_Data!W700 -> Wallet | F13: =Ecommerce_Data!W850 -> Debit Card
A14: Sales_Channel | B14: =Ecommerce_Data!X250 -> Mobile App | C14: =Ecommerce_Data!X200 -> Marketplace | D14: =Ecommerce_Data!X550 -> Mobile App | E14: =Ecommerce_Data!X700 -> Website | F14: =Ecommerce_Data!X850 -> Website
A15: Shipping_Mode | B15: =Ecommerce_Data!Y250 -> Standard | C15: =Ecommerce_Data!Y200 -> Express | D15: =Ecommerce_Data!Y550 -> Standard | E15: =Ecommerce_Data!Y700 -> Same Day | F15: =Ecommerce_Data!Y850 -> Express
A16: Order_Status | B16: =Ecommerce_Data!Z250 -> Delivered | C16: =Ecommerce_Data!Z200 -> Delivered | D16: =Ecommerce_Data!Z550 -> Delivered | E16: =Ecommerce_Data!Z700 -> Shipped | F16: =Ecommerce_Data!Z850 -> Delivered
A19: Q1. Find the Customer Name for Order 1 using HLOOKUP. | F19: =HLOOKUP(B2,$B$2:$F$16,2,0) -> Customer 734
A21: Q2. Find the Category for Order 3 using HLOOKUP. | F21: =HLOOKUP(D2,$B$2:$F$16,4,0) -> Home & Kitchen
A23: Q3. Find the Gross Sales for Order 2 using HLOOKUP. | F23: =HLOOKUP(C2,$B$2:$F$16,8,0) -> 7800
A25: Q4. Find the Profit for Order 4 using HLOOKUP. | F25: =HLOOKUP(E2,$B$2:$F$16,10,0) -> 761.51
A27: Q5. Find the City for Order 5 using HLOOKUP. | F27: =HLOOKUP(F2,$B$2:$F$16,11,0) -> Chennai
A29: Q6. Find the Payment Method for Order 1 using HLOOKUP. | F29: =HLOOKUP(B2,$B$2:$F$16,12,0) -> Net Banking
A31: Q7. Find the Shipping Mode for Order 3 using HLOOKUP. | F31: =HLOOKUP(D2,$B$2:$F$16,14,0) -> Standard
A33: Q8. Find the Order Status for Order 4 using HLOOKUP. | F33: =HLOOKUP(E2,$B$2:$F$16,15,0) -> Shipped
A35: Q9. Find the Sales Channel for Order 2 using HLOOKUP. | F35: =HLOOKUP(C2,$B$2:$F$16,13,0) -> Marketplace
A37: Q10. Find the Discount % for Order 5 using HLOOKUP. | F37: =HLOOKUP(F2,$B$2:$F$16,7,0) -> 15

Sheet INDEX + MATCH
A1: Q1. Find the Customer Name for the Order in Row 420. | H1: =INDEX(Ecommerce_Data!$D$2:$D$12001,MATCH(Ecommerce_Data!A420,Ecommerce_Data!$A$2:$A$12001,0)) -> Customer 2273
A3: Q2. Find the Customer Type for the Order in Row 930. | H3: =INDEX(Ecommerce_Data!$F$2:$F$12001,MATCH(Ecommerce_Data!A930,Ecommerce_Data!$A$2:$A$12001,0)) -> Returning
A5: Q3. Find the Customer Age for the Order in Row 675. | H5: =INDEX(Ecommerce_Data!$E$2:$E$12001,MATCH(Ecommerce_Data!A675,Ecommerce_Data!$A$2:$A$12001,0)) -> 48
A7: Q4. Find the Product Name for the order in Row 1450. | H7: =INDEX(Ecommerce_Data!$H$2:$H$12001,MATCH(Ecommerce_Data!A1450,Ecommerce_Data!$A$2:$A$12001,0)) -> Keyboard
A9: Q5. Find the Supplier for the order in Row 1980. | H9: =INDEX(Ecommerce_Data!$J$2:$J$12001,MATCH(Ecommerce_Data!A1980,Ecommerce_Data!$A$2:$A$12001,0)) -> FashionMart
A11: Q6. Find the Quantity purchased in the order in Row 2250. | H11: =INDEX(Ecommerce_Data!$K$2:$K$12001,MATCH(Ecommerce_Data!A2250,Ecommerce_Data!$A$2:$A$12001,0)) -> 2
A13: Q7. Find the Discount % for the order in Row 2790. | H13: =INDEX(Ecommerce_Data!$M$2:$M$12001,MATCH(Ecommerce_Data!A2790,Ecommerce_Data!$A$2:$A$12001,0)) -> 5
A15: Q8. Find the profit for the order in Row 4140. | H15: =INDEX(Ecommerce_Data!$R$2:$R$12001,MATCH(Ecommerce_Data!A4140,Ecommerce_Data!$A$2:$A$12001,0)) -> 1585.16
A17: Q9. Find the Customer Segment for the order in Row 4410. | H17: =INDEX(Ecommerce_Data!$S$2:$S$12001,MATCH(Ecommerce_Data!A4410,Ecommerce_Data!$A$2:$A$12001,0)) -> Consumer
A19: Q10. Find the State for the order in Row 4950. | H19: =INDEX(Ecommerce_Data!$U$2:$U$12001,MATCH(Ecommerce_Data!A4950,Ecommerce_Data!$A$2:$A$12001,0)) -> Karnataka
A21: Q11. Find the Sales Channel for the order in Row 5490. | H21: =INDEX(Ecommerce_Data!$X$2:$X$12001,MATCH(Ecommerce_Data!A5490,Ecommerce_Data!$A$2:$A$12001,0)) -> Marketplace
A23: Q12. Find the Priority Order status for the order in Row 6570. | H23: =INDEX(Ecommerce_Data!$AB$2:$AB$12001,MATCH(Ecommerce_Data!A6570,Ecommerce_Data!$A$2:$A$12001,0)) -> No

Sheet Conditional_Formatting
A1: Order_ID | B1: Customer_Name | C1: Product_Name | D1: Quantity | E1: Discount_% | F1: Net_Sales | G1: Profit | H1: Order_Status
A2: =Ecommerce_Data!A250 -> ORD501194 | B2: =Ecommerce_Data!D250 -> Customer 734 | C2: =Ecommerce_Data!H250 -> Calculator | D2: =Ecommerce_Data!K250 -> 4 | E2: =Ecommerce_Data!M250 -> 15 | F2: =Ecommerce_Data!P250 -> 2210 | G2: =Ecommerce_Data!R250 -> 822.61 | H2: =Ecommerce_Data!Z250 -> Delivered
A3: =Ecommerce_Data!A400 -> ORD502140 | B3: =Ecommerce_Data!D400 -> Customer 1817 | C3: =Ecommerce_Data!H400 -> Power Bank | D3: =Ecommerce_Data!K400 -> 1 | E3: =Ecommerce_Data!M400 -> 0 | F3: =Ecommerce_Data!P400 -> 1600 | G3: =Ecommerce_Data!R400 -> 425.24 | H3: =Ecommerce_Data!Z400 -> Delivered
A4: =Ecommerce_Data!A550 -> ORD510622 | B4: =Ecommerce_Data!D550 -> Customer 1481 | C4: =Ecommerce_Data!H550 -> Coffee Maker | D4: =Ecommerce_Data!K550 -> 1 | E4: =Ecommerce_Data!M550 -> 10 | F4: =Ecommerce_Data!P550 -> 3780 | G4: =Ecommerce_Data!R550 -> 1353.11 | H4: =Ecommerce_Data!Z550 -> Delivered
A5: =Ecommerce_Data!A700 -> ORD507461 | B5: =Ecommerce_Data!D700 -> Customer 2437 | C5: =Ecommerce_Data!H700 -> Formal Shirt | D5: =Ecommerce_Data!K700 -> 2 | E5: =Ecommerce_Data!M700 -> 20 | F5: =Ecommerce_Data!P700 -> 2720 | G5: =Ecommerce_Data!R700 -> 761.51 | H5: =Ecommerce_Data!Z700 -> Shipped
A6: =Ecommerce_Data!A850 -> ORD511472 | B6: =Ecommerce_Data!D850 -> Customer 701 | C6: =Ecommerce_Data!H850 -> Womens Kurti | D6: =Ecommerce_Data!K850 -> 4 | E6: =Ecommerce_Data!M850 -> 15 | F6: =Ecommerce_Data!P850 -> 4760 | G6: =Ecommerce_Data!R850 -> 1885.01 | H6: =Ecommerce_Data!Z850 -> Delivered
A7: =Ecommerce_Data!A1000 -> ORD505264 | B7: =Ecommerce_Data!D1000 -> Customer 2400 | C7: =Ecommerce_Data!H1000 -> Vacuum Cleaner | D7: =Ecommerce_Data!K1000 -> 4 | E7: =Ecommerce_Data!M1000 -> 5 | F7: =Ecommerce_Data!P1000 -> 32300 | G7: =Ecommerce_Data!R1000 -> 11549.54 | H7: =Ecommerce_Data!Z1000 -> Delivered
A8: =Ecommerce_Data!A1150 -> ORD500919 | B8: =Ecommerce_Data!D1150 -> Customer 1739 | C8: =Ecommerce_Data!H1150 -> Running Shoes | D8: =Ecommerce_Data!K1150 -> 3 | E8: =Ecommerce_Data!M1150 -> 20 | F8: =Ecommerce_Data!P1150 -> 7680 | G8: =Ecommerce_Data!R1150 -> 1646.7 | H8: =Ecommerce_Data!Z1150 -> Delivered
A9: =Ecommerce_Data!A1300 -> ORD509784 | B9: =Ecommerce_Data!D1300 -> Customer 2052 | C9: =Ecommerce_Data!H1300 -> Mouse | D9: =Ecommerce_Data!K1300 -> 1 | E9: =Ecommerce_Data!M1300 -> 20 | F9: =Ecommerce_Data!P1300 -> 720 | G9: =Ecommerce_Data!R1300 -> 149.78 | H9: =Ecommerce_Data!Z1300 -> Processing
A10: =Ecommerce_Data!A1450 -> ORD505155 | B10: =Ecommerce_Data!D1450 -> Customer 921 | C10: =Ecommerce_Data!H1450 -> Keyboard | D10: =Ecommerce_Data!K1450 -> 2 | E10: =Ecommerce_Data!M1450 -> 5 | F10: =Ecommerce_Data!P1450 -> 3420 | G10: =Ecommerce_Data!R1450 -> 954.12 | H10: =Ecommerce_Data!Z1450 -> Delivered
A11: =Ecommerce_Data!A1600 -> ORD500660 | B11: =Ecommerce_Data!D1600 -> Customer 1019 | C11: =Ecommerce_Data!H1600 -> Calculator | D11: =Ecommerce_Data!K1600 -> 4 | E11: =Ecommerce_Data!M1600 -> 10 | F11: =Ecommerce_Data!P1600 -> 2340 | G11: =Ecommerce_Data!R1600 -> 644.02 | H11: =Ecommerce_Data!Z1600 -> Delivered
A14: Q1. Highlight Net Sales Greater than ₹5000. | J14: Q2. Highlight orders where Quantity is 3 or more.
A16: Order_ID | B16: Customer_Name | C16: Product_Name | D16: Quantity | E16: Discount_% | F16: Net_Sales | G16: Profit | H16: Order_Status | J16: Order_ID | K16: Customer_Name | L16: Product_Name | M16: Quantity | N16: Discount_% | O16: Net_Sales | P16: Profit | Q16: Order_Status
A17: ORD501194 | B17: Customer 734 | C17: Calculator | D17: 4 | E17: 15 | F17: 2210 | G17: 822.61 | H17: Delivered | J17: ORD501194 | K17: Customer 734 | L17: Calculator | M17: 4 | N17: 15 | O17: 2210 | P17: 822.61 | Q17: Delivered
A18: ORD502140 | B18: Customer 1817 | C18: Power Bank | D18: 1 | E18: 0 | F18: 1600 | G18: 425.24 | H18: Delivered | J18: ORD502140 | K18: Customer 1817 | L18: Power Bank | M18: 1 | N18: 0 | O18: 1600 | P18: 425.24 | Q18: Delivered
A19: ORD510622 | B19: Customer 1481 | C19: Coffee Maker | D19: 1 | E19: 10 | F19: 3780 | G19: 1353.11 | H19: Delivered | J19: ORD510622 | K19: Customer 1481 | L19: Coffee Maker | M19: 1 | N19: 10 | O19: 3780 | P19: 1353.11 | Q19: Delivered
A20: ORD507461 | B20: Customer 2437 | C20: Formal Shirt | D20: 2 | E20: 20 | F20: 2720 | G20: 761.51 | H20: Shipped | J20: ORD507461 | K20: Customer 2437 | L20: Formal Shirt | M20: 2 | N20: 20 | O20: 2720 | P20: 761.51 | Q20: Shipped
A21: ORD511472 | B21: Customer 701 | C21: Womens Kurti | D21: 4 | E21: 15 | F21: 4760 | G21: 1885.01 | H21: Delivered | J21: ORD511472 | K21: Customer 701 | L21: Womens Kurti | M21: 4 | N21: 15 | O21: 4760 | P21: 1885.01 | Q21: Delivered
A22: ORD505264 | B22: Customer 2400 | C22: Vacuum Cleaner | D22: 4 | E22: 5 | F22: 32300 | G22: 11549.54 | H22: Delivered | J22: ORD505264 | K22: Customer 2400 | L22: Vacuum Cleaner | M22: 4 | N22: 5 | O22: 32300 | P22: 11549.54 | Q22: Delivered
A23: ORD500919 | B23: Customer 1739 | C23: Running Shoes | D23: 3 | E23: 20 | F23: 7680 | G23: 1646.7 | H23: Delivered | J23: ORD500919 | K23: Customer 1739 | L23: Running Shoes | M23: 3 | N23: 20 | O23: 7680 | P23: 1646.7 | Q23: Delivered
A24: ORD509784 | B24: Customer 2052 | C24: Mouse | D24: 1 | E24: 20 | F24: 720 | G24: 149.78 | H24: Processing | J24: ORD509784 | K24: Customer 2052 | L24: Mouse | M24: 1 | N24: 20 | O24: 720 | P24: 149.78 | Q24: Processing
A25: ORD505155 | B25: Customer 921 | C25: Keyboard | D25: 2 | E25: 5 | F25: 3420 | G25: 954.12 | H25: Delivered | J25: ORD505155 | K25: Customer 921 | L25: Keyboard | M25: 2 | N25: 5 | O25: 3420 | P25: 954.12 | Q25: Delivered
A26: ORD500660 | B26: Customer 1019 | C26: Calculator | D26: 4 | E26: 10 | F26: 2340 | G26: 644.02 | H26: Delivered | J26: ORD500660 | K26: Customer 1019 | L26: Calculator | M26: 4 | N26: 10 | O26: 2340 | P26: 644.02 | Q26: Delivered
A28: Q3. Highlight profit greater than ₹10000. | J28: Q4. Highlight orders where discount is grater than 15%.
A30: Order_ID | B30: Customer_Name | C30: Product_Name | D30: Quantity | E30: Discount_% | F30: Net_Sales | G30: Profit | H30: Order_Status | J30: Order_ID | K30: Customer_Name | L30: Product_Name | M30: Quantity | N30: Discount_% | O30: Net_Sales | P30: Profit | Q30: Order_Status
A31: ORD501194 | B31: Customer 734 | C31: Calculator | D31: 4 | E31: 15 | F31: 2210 | G31: 822.61 | H31: Delivered | J31: ORD501194 | K31: Customer 734 | L31: Calculator | M31: 4 | N31: 15 | O31: 2210 | P31: 822.61 | Q31: Delivered
A32: ORD502140 | B32: Customer 1817 | C32: Power Bank | D32: 1 | E32: 0 | F32: 1600 | G32: 425.24 | H32: Delivered | J32: ORD502140 | K32: Customer 1817 | L32: Power Bank | M32: 1 | N32: 0 | O32: 1600 | P32: 425.24 | Q32: Delivered
A33: ORD510622 | B33: Customer 1481 | C33: Coffee Maker | D33: 1 | E33: 10 | F33: 3780 | G33: 1353.11 | H33: Delivered | J33: ORD510622 | K33: Customer 1481 | L33: Coffee Maker | M33: 1 | N33: 10 | O33: 3780 | P33: 1353.11 | Q33: Delivered
A34: ORD507461 | B34: Customer 2437 | C34: Formal Shirt | D34: 2 | E34: 20 | F34: 2720 | G34: 761.51 | H34: Shipped | J34: ORD507461 | K34: Customer 2437 | L34: Formal Shirt | M34: 2 | N34: 20 | O34: 2720 | P34: 761.51 | Q34: Shipped
A35: ORD511472 | B35: Customer 701 | C35: Womens Kurti | D35: 4 | E35: 15 | F35: 4760 | G35: 1885.01 | H35: Delivered | J35: ORD511472 | K35: Customer 701 | L35: Womens Kurti | M35: 4 | N35: 15 | O35: 4760 | P35: 1885.01 | Q35: Delivered
A36: ORD505264 | B36: Customer 2400 | C36: Vacuum Cleaner | D36: 4 | E36: 5 | F36: 32300 | G36: 11549.54 | H36: Delivered | J36: ORD505264 | K36: Customer 2400 | L36: Vacuum Cleaner | M36: 4 | N36: 5 | O36: 32300 | P36: 11549.54 | Q36: Delivered
A37: ORD500919 | B37: Customer 1739 | C37: Running Shoes | D37: 3 | E37: 20 | F37: 7680 | G37: 1646.7 | H37: Delivered | J37: ORD500919 | K37: Customer 1739 | L37: Running Shoes | M37: 3 | N37: 20 | O37: 7680 | P37: 1646.7 | Q37: Delivered
A38: ORD509784 | B38: Customer 2052 | C38: Mouse | D38: 1 | E38: 20 | F38: 720 | G38: 149.78 | H38: Processing | J38: ORD509784 | K38: Customer 2052 | L38: Mouse | M38: 1 | N38: 20 | O38: 720 | P38: 149.78 | Q38: Processing
A39: ORD505155 | B39: Customer 921 | C39: Keyboard | D39: 2 | E39: 5 | F39: 3420 | G39: 954.12 | H39: Delivered | J39: ORD505155 | K39: Customer 921 | L39: Keyboard | M39: 2 | N39: 5 | O39: 3420 | P39: 954.12 | Q39: Delivered
A40: ORD500660 | B40: Customer 1019 | C40: Calculator | D40: 4 | E40: 10 | F40: 2340 | G40: 644.02 | H40: Delivered | J40: ORD500660 | K40: Customer 1019 | L40: Calculator | M40: 4 | N40: 10 | O40: 2340 | P40: 644.02 | Q40: Delivered
A42: Q5. Highlight the entire order row when the Order Status is Shipped. | J42: Q6. Highlight the entire row when Quantity is at least 3 AND Discount is at least 15%.
A44: Order_ID | B44: Customer_Name | C44: Product_Name | D44: Quantity | E44: Discount_% | F44: Net_Sales | G44: Profit | H44: Order_Status | J44: Order_ID | K44: Customer_Name | L44: Product_Name | M44: Quantity | N44: Discount_% | O44: Net_Sales | P44: Profit | Q44: Order_Status
A45: ORD501194 | B45: Customer 734 | C45: Calculator | D45: 4 | E45: 15 | F45: 2210 | G45: 822.61 | H45: Delivered | J45: ORD501194 | K45: Customer 734 | L45: Calculator | M45: 4 | N45: 15 | O45: 2210 | P45: 822.61 | Q45: Delivered
A46: ORD502140 | B46: Customer 1817 | C46: Power Bank | D46: 1 | E46: 0 | F46: 1600 | G46: 425.24 | H46: Delivered | J46: ORD502140 | K46: Customer 1817 | L46: Power Bank | M46: 1 | N46: 0 | O46: 1600 | P46: 425.24 | Q46: Delivered
A47: ORD510622 | B47: Customer 1481 | C47: Coffee Maker | D47: 1 | E47: 10 | F47: 3780 | G47: 1353.11 | H47: Delivered | J47: ORD510622 | K47: Customer 1481 | L47: Coffee Maker | M47: 1 | N47: 10 | O47: 3780 | P47: 1353.11 | Q47: Delivered
...

Sheet Sort_&_Filter
A1: Order_ID | B1: Customer_Name | C1: Product_Name | D1: Quantity | E1: Discount_% | F1: Net_Sales | G1: Profit | H1: Order_Status
A2: =Ecommerce_Data!A250 -> ORD501194 | B2: =Ecommerce_Data!D250 -> Customer 734 | C2: =Ecommerce_Data!H250 -> Calculator | D2: =Ecommerce_Data!K250 -> 4 | E2: =Ecommerce_Data!M250 -> 15 | F2: =Ecommerce_Data!P250 -> 2210 | G2: =Ecommerce_Data!R250 -> 822.61 | H2: =Ecommerce_Data!Z250 -> Delivered
A3: =Ecommerce_Data!A400 -> ORD502140 | B3: =Ecommerce_Data!D400 -> Customer 1817 | C3: =Ecommerce_Data!H400 -> Power Bank | D3: =Ecommerce_Data!K400 -> 1 | E3: =Ecommerce_Data!M400 -> 0 | F3: =Ecommerce_Data!P400 -> 1600 | G3: =Ecommerce_Data!R400 -> 425.24 | H3: =Ecommerce_Data!Z400 -> Delivered
A4: =Ecommerce_Data!A550 -> ORD510622 | B4: =Ecommerce_Data!D550 -> Customer 1481 | C4: =Ecommerce_Data!H550 -> Coffee Maker | D4: =Ecommerce_Data!K550 -> 1 | E4: =Ecommerce_Data!M550 -> 10 | F4: =Ecommerce_Data!P550 -> 3780 | G4: =Ecommerce_Data!R550 -> 1353.11 | H4: =Ecommerce_Data!Z550 -> Delivered
A5: =Ecommerce_Data!A700 -> ORD507461 | B5: =Ecommerce_Data!D700 -> Customer 2437 | C5: =Ecommerce_Data!H700 -> Formal Shirt | D5: =Ecommerce_Data!K700 -> 2 | E5: =Ecommerce_Data!M700 -> 20 | F5: =Ecommerce_Data!P700 -> 2720 | G5: =Ecommerce_Data!R700 -> 761.51 | H5: =Ecommerce_Data!Z700 -> Shipped
A6: =Ecommerce_Data!A850 -> ORD511472 | B6: =Ecommerce_Data!D850 -> Customer 701 | C6: =Ecommerce_Data!H850 -> Womens Kurti | D6: =Ecommerce_Data!K850 -> 4 | E6: =Ecommerce_Data!M850 -> 15 | F6: =Ecommerce_Data!P850 -> 4760 | G6: =Ecommerce_Data!R850 -> 1885.01 | H6: =Ecommerce_Data!Z850 -> Delivered
A7: =Ecommerce_Data!A1000 -> ORD505264 | B7: =Ecommerce_Data!D1000 -> Customer 2400 | C7: =Ecommerce_Data!H1000 -> Vacuum Cleaner | D7: =Ecommerce_Data!K1000 -> 4 | E7: =Ecommerce_Data!M1000 -> 5 | F7: =Ecommerce_Data!P1000 -> 32300 | G7: =Ecommerce_Data!R1000 -> 11549.54 | H7: =Ecommerce_Data!Z1000 -> Delivered
A8: =Ecommerce_Data!A1150 -> ORD500919 | B8: =Ecommerce_Data!D1150 -> Customer 1739 | C8: =Ecommerce_Data!H1150 -> Running Shoes | D8: =Ecommerce_Data!K1150 -> 3 | E8: =Ecommerce_Data!M1150 -> 20 | F8: =Ecommerce_Data!P1150 -> 7680 | G8: =Ecommerce_Data!R1150 -> 1646.7 | H8: =Ecommerce_Data!Z1150 -> Delivered
A9: =Ecommerce_Data!A1300 -> ORD509784 | B9: =Ecommerce_Data!D1300 -> Customer 2052 | C9: =Ecommerce_Data!H1300 -> Mouse | D9: =Ecommerce_Data!K1300 -> 1 | E9: =Ecommerce_Data!M1300 -> 20 | F9: =Ecommerce_Data!P1300 -> 720 | G9: =Ecommerce_Data!R1300 -> 149.78 | H9: =Ecommerce_Data!Z1300 -> Processing
A10: =Ecommerce_Data!A1450 -> ORD505155 | B10: =Ecommerce_Data!D1450 -> Customer 921 | C10: =Ecommerce_Data!H1450 -> Keyboard | D10: =Ecommerce_Data!K1450 -> 2 | E10: =Ecommerce_Data!M1450 -> 5 | F10: =Ecommerce_Data!P1450 -> 3420 | G10: =Ecommerce_Data!R1450 -> 954.12 | H10: =Ecommerce_Data!Z1450 -> Delivered
A11: =Ecommerce_Data!A1600 -> ORD500660 | B11: =Ecommerce_Data!D1600 -> Customer 1019 | C11: =Ecommerce_Data!H1600 -> Calculator | D11: =Ecommerce_Data!K1600 -> 4 | E11: =Ecommerce_Data!M1600 -> 10 | F11: =Ecommerce_Data!P1600 -> 2340 | G11: =Ecommerce_Data!R1600 -> 644.02 | H11: =Ecommerce_Data!Z1600 -> Delivered
A13: Q1. Sort the selected orders by Net Sales from Largest to Smallest. | J13: Q2. Sort the orders by Quantity from Largest to Smallest.
A15: Order_ID | B15: Customer_Name | C15: Product_Name | D15: Quantity | E15: Discount_% | F15: Net_Sales | G15: Profit | H15: Order_Status | J15: Order_ID | K15: Customer_Name | L15: Product_Name | M15: Quantity | N15: Discount_% | O15: Net_Sales | P15: Profit | Q15: Order_Status
A16: ORD505264 | B16: Customer 2400 | C16: Vacuum Cleaner | D16: 4 | E16: 5 | F16: 32300 | G16: 11549.54 | H16: Delivered | J16: ORD501194 | K16: Customer 734 | L16: Calculator | M16: 4 | N16: 15 | O16: 2210 | P16: 822.61 | Q16: Delivered
A17: ORD500919 | B17: Customer 1739 | C17: Running Shoes | D17: 3 | E17: 20 | F17: 7680 | G17: 1646.7 | H17: Delivered | J17: ORD511472 | K17: Customer 701 | L17: Womens Kurti | M17: 4 | N17: 15 | O17: 4760 | P17: 1885.01 | Q17: Delivered
A18: ORD511472 | B18: Customer 701 | C18: Womens Kurti | D18: 4 | E18: 15 | F18: 4760 | G18: 1885.01 | H18: Delivered | J18: ORD505264 | K18: Customer 2400 | L18: Vacuum Cleaner | M18: 4 | N18: 5 | O18: 32300 | P18: 11549.54 | Q18: Delivered
A19: ORD510622 | B19: Customer 1481 | C19: Coffee Maker | D19: 1 | E19: 10 | F19: 3780 | G19: 1353.11 | H19: Delivered | J19: ORD500660 | K19: Customer 1019 | L19: Calculator | M19: 4 | N19: 10 | O19: 2340 | P19: 644.02 | Q19: Delivered
A20: ORD505155 | B20: Customer 921 | C20: Keyboard | D20: 2 | E20: 5 | F20: 3420 | G20: 954.12 | H20: Delivered | J20: ORD500919 | K20: Customer 1739 | L20: Running Shoes | M20: 3 | N20: 20 | O20: 7680 | P20: 1646.7 | Q20: Delivered
A21: ORD507461 | B21: Customer 2437 | C21: Formal Shirt | D21: 2 | E21: 20 | F21: 2720 | G21: 761.51 | H21: Shipped | J21: ORD507461 | K21: Customer 2437 | L21: Formal Shirt | M21: 2 | N21: 20 | O21: 2720 | P21: 761.51 | Q21: Shipped
A22: ORD500660 | B22: Customer 1019 | C22: Calculator | D22: 4 | E22: 10 | F22: 2340 | G22: 644.02 | H22: Delivered | J22: ORD505155 | K22: Customer 921 | L22: Keyboard | M22: 2 | N22: 5 | O22: 3420 | P22: 954.12 | Q22: Delivered
A23: ORD501194 | B23: Customer 734 | C23: Calculator | D23: 4 | E23: 15 | F23: 2210 | G23: 822.61 | H23: Delivered | J23: ORD502140 | K23: Customer 1817 | L23: Power Bank | M23: 1 | N23: 0 | O23: 1600 | P23: 425.24 | Q23: Delivered
A24: ORD502140 | B24: Customer 1817 | C24: Power Bank | D24: 1 | E24: 0 | F24: 1600 | G24: 425.24 | H24: Delivered | J24: ORD510622 | K24: Customer 1481 | L24: Coffee Maker | M24: 1 | N24: 10 | O24: 3780 | P24: 1353.11 | Q24: Delivered
A25: ORD509784 | B25: Customer 2052 | C25: Mouse | D25: 1 | E25: 20 | F25: 720 | G25: 149.78 | H25: Processing | J25: ORD509784 | K25: Customer 2052 | L25: Mouse | M25: 1 | N25: 20 | O25: 720 | P25: 149.78 | Q25: Processing
A28: Q3. Sort the Profit from Smallest to Largest. | J28: Q4. Sort the data first by Product_Name and then by Net_Sales from largest to smallest.
A30: Order_ID | B30: Customer_Name | C30: Product_Name | D30: Quantity | E30: Discount_% | F30: Net_Sales | G30: Profit | H30: Order_Status | J30: Order_ID | K30: Customer_Name | L30: Product_Name | M30: Quantity | N30: Discount_% | O30: Net_Sales | P30: Profit | Q30: Order_Status
A31: ORD509784 | B31: Customer 2052 | C31: Mouse | D31: 1 | E31: 20 | F31: 720 | G31: 149.78 | H31: Processing | J31: ORD500660 | K31: Customer 1019 | L31: Calculator | M31: 4 | N31: 10 | O31: 2340 | P31: 644.02 | Q31: Delivered
A32: ORD502140 | B32: Customer 1817 | C32: Power Bank | D32: 1 | E32: 0 | F32: 1600 | G32: 425.24 | H32: Delivered | J32: ORD501194 | K32: Customer 734 | L32: Calculator | M32: 4 | N32: 15 | O32: 2210 | P32: 822.61 | Q32: Delivered
A33: ORD500660 | B33: Customer 1019 | C33: Calculator | D33: 4 | E33: 10 | F33: 2340 | G33: 644.02 | H33: Delivered | J33: ORD510622 | K33: Customer 1481 | L33: Coffee Maker | M33: 1 | N33: 10 | O33: 3780 | P33: 1353.11 | Q33: Delivered
A34: ORD507461 | B34: Customer 2437 | C34: Formal Shirt | D34: 2 | E34: 20 | F34: 2720 | G34: 761.51 | H34: Shipped | J34: ORD507461 | K34: Customer 2437 | L34: Formal Shirt | M34: 2 | N34: 20 | O34: 2720 | P34: 761.51 | Q34: Shipped
A35: ORD501194 | B35: Customer 734 | C35: Calculator | D35: 4 | E35: 15 | F35: 2210 | G35: 822.61 | H35: Delivered | J35: ORD505155 | K35: Customer 921 | L35: Keyboard | M35: 2 | N35: 5 | O35: 3420 | P35: 954.12 | Q35: Delivered
A36: ORD505155 | B36: Customer 921 | C36: Keyboard | D36: 2 | E36: 5 | F36: 3420 | G36: 954.12 | H36: Delivered | J36: ORD509784 | K36: Customer 2052 | L36: Mouse | M36: 1 | N36: 20 | O36: 720 | P36: 149.78 | Q36: Processing
A37: ORD510622 | B37: Customer 1481 | C37: Coffee Maker | D37: 1 | E37: 10 | F37: 3780 | G37: 1353.11 | H37: Delivered | J37: ORD502140 | K37: Customer 1817 | L37: Power Bank | M37: 1 | N37: 0 | O37: 1600 | P37: 425.24 | Q37: Delivered
A38: ORD500919 | B38: Customer 1739 | C38: Running Shoes | D38: 3 | E38: 20 | F38: 7680 | G38: 1646.7 | H38: Delivered | J38: ORD500919 | K38: Customer 1739 | L38: Running Shoes | M38: 3 | N38: 20 | O38: 7680 | P38: 1646.7 | Q38: Delivered
A39: ORD511472 | B39: Customer 701 | C39: Womens Kurti | D39: 4 | E39: 15 | F39: 4760 | G39: 1885.01 | H39: Delivered | J39: ORD505264 | K39: Customer 2400 | L39: Vacuum Cleaner | M39: 4 | N39: 5 | O39: 32300 | P39: 11549.54 | Q39: Delivered
A40: ORD505264 | B40: Customer 2400 | C40: Vacuum Cleaner | D40: 4 | E40: 5 | F40: 32300 | G40: 11549.54 | H40: Delivered | J40: ORD511472 | K40: Customer 701 | L40: Womens Kurti | M40: 4 | N40: 15 | O40: 4760 | P40: 1885.01 | Q40: Delivered
A43: Q5. Filter the data to show only orders having Calculator. | J43: Q6. Filter orders where Net Sales are Greater than ₹10,000.
A45: Order_ID | B45: Customer_Name | C45: Product_Name | D45: Quantity | E45: Discount_% | F45: Net_Sales | G45: Profit | H45: Order_Status | J45: Order_ID | K45: Customer_Name | L45: Product_Name | M45: Quantity | N45: Discount_% | O45: Net_Sales | P45: Profit | Q45: Order_Status
A46: ORD501194 | B46: Customer 734 | C46: Calculator | D46: 4 | E46: 15 | F46: 2210 | G46: 822.61 | H46: Delivered | J46: ORD505264 | K46: Customer 2400 | L46: Vacuum Cleaner | M46: 4 | N46: 5 | O46: 32300 | P46: 11549.54 | Q46: Delivered | S46: Net_Sales
A47: ORD502140 | B47: Customer 1817 | C47: Power Bank | D47: 1 | E47: 0 | F47: 1600 | G47: 425.24 | H47: Delivered | S47: >10000
A48: ORD510622 | B48: Customer 1481 | C48: Coffee Maker | D48: 1 | E48: 10 | F48: 3780 | G48: 1353.11 | H48: Delivered
...

Sheet Business_Analysis
A1: Q1. What is the total Net Sales generated from all orders? | I1: =SUM(Ecommerce_Data!P2:P12001) -> 115018425
A3: Q2. What is the total quantity of products sold? | I3: =SUM(Ecommerce_Data!K2:K12001) -> 25786
A5: Q3. What is the average Net Sales per order? | I5: =AVERAGE(Ecommerce_Data!P2:P12001) -> 9584.8687
A7: Q4. What is the average Profit per order? | I7: =AVERAGE(Ecommerce_Data!R2:R12001) -> 3007.3917
A9: Q5. What is the highest Net Sales value from a single order? | I9: =MAX(Ecommerce_Data!P2:P12001) -> 330000
A11: Q6. What is the total profit generated by "Electronics" category? | I11: =SUMIF(Ecommerce_Data!I2:I12001,"Electronics",Ecommerce_Data!R2:R12001) -> 25220570
A13: Q7. How many orders belong to the "Fashion" category? | I13: =COUNTIF(Ecommerce_Data!I2:I12001,"Fashion") -> 2584
A15: Q8. What is the total Net Sales from the "Corporate" customer segment? | I15: =SUMIF(Ecommerce_Data!S2:S12001,"Corporate",Ecommerce_Data!P2:P12001) -> 22062412
A17: Q9. How many orders were placed through the "Mobile App" sales channel? | I17: =COUNTIF(Ecommerce_Data!X2:X12001,"Mobile App") -> 4832
A19: Q10.How many orders were cancelled? | I19: =COUNTIF(Ecommerce_Data!Z2:Z12001,"Cancelled") -> 471
A21: Q11. What is the total Profit from orders that were placed through the Mobile | I21: =SUMIFS(Table1[Profit],Table1[Sales_Channel],"Mobile App",Table1[Customer_Segment],"Corporate") -> 2917283.8
A22: App AND belong to the Corporate customer segment?
A24: Q12. What is the total Profit? | I24: =SUM(Ecommerce_Data!R2:R12001) -> 36088700

Sheet Pivot_Analysis
A1: SALES BY CATEGORY | E1: PROFIT BY CUSTOMER SEGMENT | I1: SALES CHANNEL PERFORMANCE
A2: Row Labels | B2: Sum of Net_Sales | E2: Row Labels | F2: Sum of Profit | I2: Row Labels | J2: Sum of Net_Sales | K2: Count of Order_ID | L2: Sum of Profit
A3: Beauty | B3: 3215775 | E3: Consumer | F3: 21951012 | I3: Marketplace | J3: 23776678 | K3: 2369 | L3: 7427624.8
A4: Books & Stationery | B4: 1582650 | E4: Corporate | F4: 6954594.6 | I4: Mobile App | J4: 45499405 | K4: 4832 | L4: 14393827
A5: Electronics | B5: 80385345 | E5: Home Office | F5: 7183094 | I5: Website | J5: 45742342 | K5: 4799 | L5: 14267249
A6: Fashion | B6: 10892375 | E6: Grand Total | F6: 36088700 | I6: Grand Total | J6: 115018425 | K6: 12000 | L6: 36088700
A7: Home & Kitchen | B7: 18942280
A8: Grand Total | B8: 115018425
B11: ORDER STATUS ANALYSIS | F11: YEARLY SALES & PROFIT
B12: Row Labels | C12: Count of Order_ID | F12: Row Labels | G12: Sum of Net_Sales | H12: Sum of Profit
B13: Cancelled | C13: 471 | F13: 2024 | G13: 43103840 | H13: 13374979
B14: Delivered | C14: 8717 | F14: 2025 | G14: 44155225 | H14: 13972768
B15: Processing | C15: 994 | F15: 2026 | G15: 27759360 | H15: 8740954
B16: Returned | C16: 502 | F16: Grand Total | G16: 115018425 | H16: 36088700
B17: Shipped | C17: 1316
B18: Grand Total | C18: 12000

Sheet Charts
A1: SECTION 1: NORMAL CHARTS
A3: NET SALES BY SALES CHANNEL | J3: PROFIT BY CUSTOMER SEGMENT
A20: SECTION 2: PIVOT CHARTS
A22: NET SALES BY CATEGORY | J22: MONTHLY NET SALES & PROFIT

Sheet Dashboard
A1: E-COMMERCE SALES DASHBOARD
A4: TOTAL SALES | D4: TOTAL PROFIT | G4: TOTAL ORDERS | J4: TOTAL QUANTITY | M4: PROFIT MARGIN
A7: 115018425 | D7: 36088700 | G7: 12000 | J7: 25786 | M7: =D7/A7 -> 0.31376451
A9: Interactive Filters available on Pivot_Analysis sheet.
A44: KEY BUSINESS INSIGHTS
A46: 1. Electronics is the highest-selling category based on total sales.
A47: 2. Total Net Sales are ₹115.02 million approximately.
A48: 3. Total Profit is ₹36.09 million approximately.
A49: 4. Overall Profit Margin is approximately 31%.
A50: 5. 2025 generated higher Net Sales and Profit than 2026.

Sheet Final_Analysis
A1: E-COMERCE FINAL ANALYSIS & BUSINESS INSIGHTS
A3: Q1. What is the total Net Sales?
A4: Answers: | B4: ₹115018425
A6: Q2. What is the total Profit?
A7: Answers: | B7: ₹36088700.14
A9: Q3. What is the total number of Orders?
A10: Answers: | B10: 12000
A12: Q4. Which category generated the highest Net Sales?
A13: Answers: | B13: Electronics | C13: 80385345
A15: Q5. Which Customer Segment generated the highest Profit?
A16: Answers: | B16: Consumer customer segment generated the highest profit of ₹21951011.55
A18: Q6. Which sales channel generated the highest Net Sales?
A19: Answers: | B19: Website | C19: 45742342
A21: Q7. Which order status has the highest no. of orders?
A22: Answers: | B22: Delivered | C22: 8717
A24: Q8. What percentage of total orders belong to the most common order status?
A25: Answers: | B25: =C22/B10 -> 0.72641667
A27: Q9. Which year generated the highest Net Sales?
A28: Answers: | B28: 2025 | C28: 44155225
A30: Q10. Which month had the highest Net Sales?
A31: Answers: | B31: 45658 | C31: 4236507.5
A34: FINAL BUSINESS INSIGHTS
A36: INSIGHT 1
A37: The category with the highest Net Sales is ELECTRONICS, indicating strong customer demand for this category.
A39: INSIGHT 2
A40: The CONSUMER customer segment contributes the highest profit, making it an important segment for the business.
A42: INSIGHT 3
A43: WEBSITE is the strongest sales channel based on Net Sales.
A45: INSIGHT 4
A46: The month with the highest Net sales was JANUARY, indicating a period of particularly strong business performance.
A49: BUSINESS RECOMMENDATIONS
A51: The company should focus on the Highest-Performing category and maintain sufficient inventory for it.
A52: The company should investigate low-performing months/categories to identify opportunities for improvement.
